<?xml version="1.0" ?>
<sdf version="1.9">
  <model name="blueye" canonical_link="blueye_link">
    <link name="blueye_link">
      <!--Main model link-->
      <pose relative_to="__model__">0.0 0.0 0.0 3.1415 0.0 0.0</pose> 
      <visual name="blueye_visual">
        <pose relative_to="blueye_link">-0.325 0.144 0.05 1.5707 3.1415 1.5707</pose>
        <geometry>
          <mesh>
            <uri>model://models/dynamic_assets/blueye/meshes/blueye.dae</uri>
            <scale>1 1 1</scale>
          </mesh>
        </geometry>
      </visual>
      <inertial>
        <mass>22.1</mass>
        <pose>0.0 0.0 0.0 0.0 0.0 0.0</pose>
        <inertia>
          <ixx>50</ixx>
          <ixy>0</ixy>
          <ixz>0</ixz>
          <iyy>50</iyy>
          <iyz>0</iyz>
          <izz>20</izz>
        </inertia>
        <fluid_added_mass>
          <xx>5.2171</xx>
          <yy>29.8729</yy>
          <zz>19.2643</zz>
          <pp>0.0972</pp>
          <qq>0.1822</qq>
          <rr>0.1594</rr>
        </fluid_added_mass>
      </inertial>
      <collision name="blueye_collision">
        <!--Collision box for bouyancy-->
        <pose relative_to="blueye_link">0.0 0.0 -0.3 0.0 0.0 0.0</pose>
        <geometry>
          <box>
            <size>0.419 0.205 0.1025</size>
          </box>
        </geometry>
      </collision>
      <collision name="blueye_collision_2">
        <!--Collision box for bouyancy-->
        <pose relative_to="blueye_link">0.0 0.0 -0.1 0.0 0.0 0.0</pose>
        <geometry>
          <box>
            <size>0.419 0.105 0.3025</size>
          </box>
        </geometry>
        </collision>
    </link>
    
    <!-- Camera for testing of aruco code odometry -->
    <!-- Taken from https://gitlab.com/aurlab/mundus-mir-project/packages/gazebo_spesifics/gz_models/-/blob/main/models/dynamic_assets/blueye/generated.sdf?ref_type=heads -->
    
    <link name="blueye_camera_1_link">
    
    <!-- <visual name="camera_visual">
        <pose relative_to="blueye_camera_1_link">0.0. 0.0 0.0 0.0. 0.0 0.0</pose>
        <geometry>
          <box>
            <size>0.1 0.1 0.1</size>
          </box>
        </geometry>
     </visual>-->
      <pose relative_to="blueye_link">0.1 0.0 0.0 3.1416 0 0</pose>
      <sensor name="blueye_front_camera" type="camera">
        <camera>
          <image>
            <width>1920</width>
            <height>1080</height>
          </image>
          <horizontal_fov>1.48</horizontal_fov>
          <clip>
            <far>10.0</far>
            <near>0.1</near>
          </clip>
          <camera_info_topic>/blueye/camera/front_camera/camera_info</camera_info_topic>
        </camera>
        <always_on>1</always_on>
        <update_rate>10</update_rate>
        <topic>/blueye/camera/front_camera/image_raw</topic>
        <visualize>1</visualize>
      </sensor>
      <inertial>
        <mass>0.0001</mass>
      </inertial>
    </link>

    <joint name="blueye_camera_1_joint" type="fixed">
      <child>blueye_camera_1_link</child>
      <parent>blueye_link</parent>
    </joint>

    <plugin name="gz::sim::systems::OdometryPublisher" filename="gz-sim-odometry-publisher-system">
      <!--Ground Truth Position-->
      <frame>world_flu</frame>
      <!--robot_base_frame>blueye_link</robot_base_frame-->
      <robot_base_frame>"__model__"</robot_base_frame>
      <odom_topic>blueye/odometry_enu/gt</odom_topic>
      <dimensions>3</dimensions>
    </plugin>
    <link name="blueye_imu_link">
      <!--IMU Sensor Link-->
      <pose relative_to="blueye_link">0.0 0.0 0.0 0.0 0.0 0.0</pose>
      <sensor name="blueye_imu" type="imu">
        <update_rate>1000</update_rate>
        <topic>/blueye/imu</topic>
        <imu>
          <linear_acceleration>
            <x>
              <noise type="gaussian">
                <mean>0.0</mean>
                <stddev>0.0</stddev>
                <bias_mean>0.0</bias_mean>
                <bias_stddev>0.0</bias_stddev>
              </noise>
            </x>
            <y>
              <noise type="gaussian">
                <mean>0.0</mean>
                <stddev>0.0</stddev>
                <bias_mean>0.0</bias_mean>
                <bias_stddev>0.0</bias_stddev>
              </noise>
            </y>
            <z>
              <noise type="gaussian">
                <mean>0.0</mean>
                <stddev>0.0</stddev>
                <bias_mean>0.0</bias_mean>
                <bias_stddev>0.0</bias_stddev>
              </noise>
            </z>
          </linear_acceleration>
          <angular_velocity>
            <x>
              <noise type="gaussian">
                <mean>0.0</mean>
                <stddev>0.0</stddev>
                <bias_mean>0.0</bias_mean>
                <bias_stddev>0.0</bias_stddev>
              </noise>
            </x>
            <y>
              <noise type="gaussian">
                <mean>0.0</mean>
                <stddev>0.0</stddev>
                <bias_mean>0.0</bias_mean>
                <bias_stddev>0.0</bias_stddev>
              </noise>
            </y>
            <z>
              <noise type="gaussian">
                <mean>0.0</mean>
                <stddev>0.0</stddev>
                <bias_mean>0.0</bias_mean>
                <bias_stddev>0.0</bias_stddev>
              </noise>
            </z>
          </angular_velocity>
        </imu>
        <always_on>1</always_on>
      </sensor>
      <inertial>
        <mass>0.0001</mass>
      </inertial>
    </link>
    <joint name="blueye_imu_joint" type="fixed">
      <!--IMU Joint-->
      <child>blueye_imu_link</child>
      <parent>blueye_link</parent>
    </joint>
    <link name="blueye_dvl_ray_link">
      <!--DVL Ray Link-->
      <pose relative_to="blueye_link">0.0 0.0 0.0 0.0 1.5758 0.0</pose>
      <sensor name="blueye_dvl_ray" type="gpu_lidar">
        <always_on>1</always_on>
        <update_rate>10</update_rate>
        <topic>/blueye/dvl/ray</topic>
        <visualize>1</visualize>
        <ray>
          <scan>
            <horizontal>
              <samples>1</samples>
              <resolution>1</resolution>
              <min_angle>-0.1</min_angle>
              <max_angle>0.1</max_angle>
            </horizontal>
            <vertical>
              <samples>1</samples>
              <resolution>1</resolution>
              <min_angle>-0.1</min_angle>
              <max_angle>0.1</max_angle>
            </vertical>
          </scan>
          <range>
            <min>0.1</min>
            <max>30.0</max>
            <resolution>0.1</resolution>
          </range>
          <noise>
            <type>gaussian</type>
            <mean>0.0</mean>
            <stddev>0.2</stddev>
          </noise>
        </ray>
      </sensor>
      <inertial>
        <mass>0.0001</mass>
      </inertial>
    </link>
    <joint name="blueye_dvl_ray_joint" type="fixed">
      <!--DVL Ray Joint-->
      <child>blueye_dvl_ray_link</child>
      <parent>blueye_link</parent>
    </joint>
    <link name="blueye_sonar_link">
      <!--Sonar Link-->
      <pose relative_to="blueye_link">0.0 0.0 0.0 0.0 0.0 0.0</pose>
      <sensor name="blueye_sonar" type="gpu_lidar">
        <always_on>1</always_on>
        <update_rate>10</update_rate>
        <topic>/blueye/sonar</topic>
        <visualize>1</visualize>
        <ray>
          <scan>
            <horizontal>
              <samples>100</samples>
              <resolution>0.1</resolution>
              <min_angle>-1.5707</min_angle>
              <max_angle>1.5707</max_angle>
            </horizontal>
            <vertical>
              <samples>100</samples>
              <resolution>0.1</resolution>
              <min_angle>-0.15</min_angle>
              <max_angle>0.15</max_angle>
            </vertical>
          </scan>
          <range>
            <min>0.5</min>
            <max>20.0</max>
            <resolution>0.1</resolution>
          </range>
          <noise>
            <type>gaussian</type>
            <mean>0.0</mean>
            <stddev>0.01</stddev>
          </noise>
        </ray>
      </sensor>
      <inertial>
        <mass>0.0001</mass>
      </inertial>
    </link>
    <joint name="blueye_sonar_joint" type="fixed">
      <!--Sonar Joint-->
      <child>blueye_sonar_link</child>
      <parent>blueye_link</parent>
    </joint>
    <link name="blueye_thruster_1_link">
      <!--Thruster 1 Link-->
      <pose relative_to="blueye_link">-0.14 0.1785 -0.004 0.0 -1.5707 0.0</pose>
      <inertial>
        <mass>0.0001</mass>
      </inertial>
    </link>
    <joint name="blueye_thruster_1_joint" type="revolute">
      <!--Thruster 1 Joint-->
      <child>blueye_thruster_1_link</child>
      <parent>blueye_link</parent>
      <axis>
        <xyz>0 0 -1</xyz>
        <limit>
          <lower>-1e+16</lower>
          <upper>1e+16</upper>
        </limit>
      </axis>
    </joint>
    <plugin name="gz::sim::systems::Thruster" filename="gz-sim-thruster-system">
      <namespace>blueye</namespace>
      <joint_name>blueye_thruster_1_joint</joint_name>
      <fluid_density>1025</fluid_density>
      <propeller_diameter>0.2</propeller_diameter>
      <max_thrust_cmd>50</max_thrust_cmd>
      <min_thrust_cmd>-50</min_thrust_cmd>
    </plugin>
    <link name="blueye_thruster_2_link">
      <!--Thruster 1 Link-->
      <pose relative_to="blueye_link">-0.14 -0.1785 -0.004 0.0 -1.5707 0.0</pose>
      <inertial>
        <mass>0.0001</mass>
      </inertial>
    </link>
    <joint name="blueye_thruster_2_joint" type="revolute">
      <!--Thruster 1 Joint-->
      <child>blueye_thruster_2_link</child>
      <parent>blueye_link</parent>
      <axis>
        <xyz>0 0 -1</xyz>
        <limit>
          <lower>-1e+16</lower>
          <upper>1e+16</upper>
        </limit>
      </axis>
    </joint>
    <plugin name="gz::sim::systems::Thruster" filename="gz-sim-thruster-system">
      <namespace>blueye</namespace>
      <joint_name>blueye_thruster_2_joint</joint_name>
      <fluid_density>1025</fluid_density>
      <propeller_diameter>0.2</propeller_diameter>
      <max_thrust_cmd>50</max_thrust_cmd>
      <min_thrust_cmd>-50</min_thrust_cmd>
    </plugin>
    <link name="blueye_thruster_3_link">
      <!--Thruster 1 Link-->
      <pose relative_to="blueye_link">0.08 -0.034 -0.004 0.0 1.57 -1.57</pose>
      <inertial>
        <mass>0.0001</mass>
      </inertial>
    </link>
    <joint name="blueye_thruster_3_joint" type="revolute">
      <!--Thruster 1 Joint-->
      <child>blueye_thruster_3_link</child>
      <parent>blueye_link</parent>
      <axis>
        <xyz>0 0 -1</xyz>
        <limit>
          <lower>-1e+16</lower>
          <upper>1e+16</upper>
        </limit>
      </axis>
    </joint>
    <plugin name="gz::sim::systems::Thruster" filename="gz-sim-thruster-system">
      <namespace>blueye</namespace>
      <joint_name>blueye_thruster_3_joint</joint_name>
      <fluid_density>1025</fluid_density>
      <propeller_diameter>0.2</propeller_diameter>
      <max_thrust_cmd>50</max_thrust_cmd>
      <min_thrust_cmd>-50</min_thrust_cmd>
    </plugin>
    <link name="blueye_thruster_4_link">
      <!--Thruster 1 Link-->
      <pose relative_to="blueye_link">0.0 0.0015 0.071 0.0 0.0 3.1415</pose>
      <inertial>
        <mass>0.0001</mass>
      </inertial>
    </link>
    <joint name="blueye_thruster_4_joint" type="revolute">
      <!--Thruster 1 Joint-->
      <child>blueye_thruster_4_link</child>
      <parent>blueye_link</parent>
      <axis>
        <xyz>0 0 -1</xyz>
        <limit>
          <lower>-1e+16</lower>
          <upper>1e+16</upper>
        </limit>
      </axis>
    </joint>
    <plugin name="gz::sim::systems::Thruster" filename="gz-sim-thruster-system">
      <namespace>blueye</namespace>
      <joint_name>blueye_thruster_4_joint</joint_name>
      <fluid_density>1025</fluid_density>
      <propeller_diameter>0.2</propeller_diameter>
      <max_thrust_cmd>50</max_thrust_cmd>
      <min_thrust_cmd>-50</min_thrust_cmd>
    </plugin>

    <plugin name="gz::sim::systems::Hydrodynamics" filename="gz-sim-hydrodynamics-system">
  <link_name>blueye_link</link_name>

  <!-- Linear Damping (force proportional to velocity) -->
  <xU>-25.0</xU>     <!-- Surge -->
  <yV>-70.0</yV>     <!-- Sway -->
  <zW>-120.0</zW>     <!-- Heave -->

  <kP>-15.5</kP>      <!-- Roll -->
  <mQ>-15.8</mQ>      <!-- Pitch -->
  <nR>-30.0</nR>      <!-- Yaw -->

  <!-- Quadratic Damping (force proportional to velocity squared) -->
  <xUabsU>-10.0</xUabsU>
  <yVabsV>-15.0</yVabsV>
  <zWabsW>-30.0</zWabsW>

  <kPabsP>-1.5</kPabsP>
  <mQabsQ>-1.5</mQabsQ>
  <nRabsR>-1.0</nRabsR>
</plugin>

  </model>
</sdf>
